Workbook
Name CaseACocher1: 'Fiche Creation Commande (P1)'!#REF!
Name CaseACocher1: 'Fiche Creation Commande (P2)'!#REF!

Sheet Fiche Creation Commande (P1)
B1: Zone avec formule
D5: Catégorie 1 | J5: Catégorie 2 | P5: Catégorie 3 | U5: Catégorie 4 | AF5: Catégorie 5 | AK5: Catégorie 6
D6: Etudes | J6: Travaux | P6: Fourniture Matériel | U6: Prestations | AF6: Maintenance | AK6: Autres
D7: Etude Avifaune, faune, flore | J7: Système Électrique Insulaire sur Mandat | P7: Appareils de manutention / levage | U7: ANALYSES HUILES ET AUTRES LIQUIDES | AF7: Maintenance de matériels d'ateliers d'énergie
D8: Etudes acoustiques | J8: Liaisons HT et THT-Four. Pylônes spéciaux U, architecturés, aéro-souterrains | P8: Appareils de mesure | U8: ASSISTANCE MOA CONSTRUCT°/COORD SECURITE | AF8: Maintenance de matériels de CCN
D9: Etudes d'impact | J9: Travaux LA-Elagage | P9: CONSOMMABLES BUREAUTIQUE ET INFORMATIQUE | U9: DEMOLITION/EVACUATION OUVRAGE TRANSPORT | AF9: Maintenance de matériels de comptage
D10: Etudes-Architecte et Maîtrise d'oeuvre | J10: Travaux LA-Fondations spéciales et GC LA | P10: Fourniture de câbles nus | U10: ENLEV/TRAIT DECHETS DANGEREUX AMIANT(DD) | AF10: Maintenance de matériels de filerie
D11: ETUDE TECHNIQUE - LIGNES AERIENNES | J11: Travaux LA-Installation, maintenance de FO | P11: Fourniture de tourets | U11: ENLEV/TRAIT DECHETS DANGEREUX AUTRES(DD) | AF11: Maintenance de matériels de protection et d'automatisme
D12: ETUDE TOPO/CARTOGRAPHIQUE-LIG AERIENNES | J12: Travaux LA-Travaux de montage LA | P12: Outillage isolé HTBT / TST | U12: ENLEV/TRAIT DECHETS DANGEREUX PCB (DD) | AF12: Maintenance de matériels de qualimétrie
D13: ETUDES GÉO-TECHNIQUES - LIGNES AÉRIENNES | J13: Travaux LA-Travaux peinture sur pylônes | P13: Petit matériel courant | U13: ENLEV/TRAIT DECHETS DANGEREUX SF6 (DD) | AF13: Maintenance de matériels de téléconduite
D14: Etudes matériels pour lignes aériennes | J14: DEPLOIEMENT ELECTRE PETIT d F+T | P14: Matériels de lignes | U14: ENLEV/TRAIT DECHETS NON DANGEREUX (DND) | AF14: Maintenance de stations de conversion
D15: ETUDE TECHNIQUE - POSTE | J15: GROS OEUVRE BATIMENT INDUSTRIEL (INVEST) | P15: Fourn, instal des systèmes de protection de postes | U15: Gardiennage | AF15: Maintenance des appareillages HTB
D16: ETUDE TOPO/CARTOGRAPHIQUE - POSTE | J16: Montage, installation des appareillages HTB | P16: Fourniture de matériels de CCN des grands postes | U16: Photomontage - Simulation 3D | AF16: Maintenance des installations de protection des postes
D17: ETUDES ESSAIS & QUALIF MATERIL CCL | J17: Montage, installation transformateurs et matériels bobinés | P17: Fourniture de matériels de CCN des postes sources | U17: Prestations de diagnostics sur installations électriques | AF17: Maintenance des transformateurs et des matériels bobinés
D18: Etudes PO-ETUDES GÉO-TECHNIQUES - POSTES | J18: Postes HT et THT-Montage, installation des matériels de compensation | P18: Fourniture de matériels de comptage | U18: SERVICES DE PRISE DE VUES AERIENNES | AF18: Maintenance et Contrôle réglementaire outillage
D19: ETUDE TOPO/CARTOGRAPHIQUE - LIG SOUTERR | J19: SND OEUVRE BATIMENT INDUSTRIEL | P19: Fourniture de matériels de filerie | U19: Transport lourd | AF19: Postes HT et THT-Maintenance des matériels de compensation
D20: Etudes LS-ETUDE GEO - TECHNIQUE | J20: SND OEUVRE BATIMENTS D'HABITATION | P20: Fourniture de matériels de protection et d'automatisme
D21: ETUDES TECHNIQUES - LIGNES SOUTERRAINES | J21: Travaux bâtiments hors installations IRT | P21: Fourniture de matériels de qualimétrie
D22: ETUDES TECHNIQUES LIGNES SOUS-MARINES | J22: TRAVAUX DE TERRASSEMENT | P22: Fourniture de matériels de téléconduite
J23: TRAVAUX GENIE CIVIL -VRD- VOIES D'ACCES | P23: FOURNITURE DE MOBILIER
J24: Travaux postes | P24: Fourniture de pièces détachées de PSEM
J25: Fonçages - Forages dirigés | P25: Fourniture de pièces détachées et sous ensembles de disj HTB
J26: Travaux Génie Civil Lignes Souterraines et déroulage | P26: Fourniture de pièces détachées et sous ensembles de sect HTB
J27: TRAVAUX LIAISON PROVISOIRE (CAB. SECS) | P27: Fourniture de postes intérieurs modulaires (PIM)
J28: Travaux LS | P28: Fourniture de postes sous enveloppe métallique HTB (PSEM)
P29: Fourniture d'équipements et accessoires de transformateurs
P30: Fourniture d'équipements stations conversion courant continu
P31: FOURNITURES DE BUREAU
P32: PIECES DETACHEES POUR MATL DE CCN
F142: % | I142: Genre | AE142: Totaux | AI142: Services
I143: POSTE | POSTE MAF | ETUDES LIAISONS | TRVX LA | TRVX LS | F.O. | CABLIERS | F.S. | SPS | AUTRES : | AB143: Page 1 | AE143: =$R$225 -> 30000 | AI143: SLAS
F144: 0.1 | I144: POSTE | AB144: Page 1+2 | AE144: ='Fiche Creation Commande (P2)'!$O$79 -> 0 | AI144: SLS
F145: 0.2 | I145: POSTE MAF | R145: oui | AB145: Page 1+2+3 | AE145: ='Fiche Creation Commande (P2)'!$O$142 -> 0 | AI145: SLA
F146: 0.3 | I146: ETUDES LIAISONS | R146: non | AE146: sous-totaux | AI146: SCC
F147: 0.4 | I147: TRAVAUX LA | AB147: Montant Page 1 | AE147: =AE143 -> 30000 | AI147: SP1
F148: 0.5 | I148: TRAVAUX LS | AB148: Montant Page 2 | AE148: =IF(AE144<>0,AE144-AE143,"") | AI148: SP2
F149: 0.6 | I149: FIBRE OPTIQUE | R149: 92 | AB149: Montant Page 3 | AE149: =IF(AE145<>0,AE145-AE144,"") | AI149: SCET
F150: 0.7 | I150: CABLIERS | R150: 94 | AI150: SPC
F151: 0.8 | I151: FONDATIONS SPECIALES | R151: Aucun | V151: se baser sur | AD151: Cde | AI151: SED
F152: 0.9 | I152: SPS | V152: Créer Cde | AI152: SIEGE
...

Sheet Fiche Creation Commande (P2)
B1: Zone avec formule
E3: Rappel de la fiche Création commande page 1 | M3: Date réception | Q3: OTP
D4: N° Cde | E4: =IF('Fiche Creation Commande (P1)'!L162<>0,'Fiche Creation Commande (P1)'!L162,"") | M4: Date de Réception Unique | O4: =IF('Fiche Creation Commande (P1)'!AB189=M4,"OUI","NON") -> NON | Q4: OTP identique pour tous les postes | S4: =IF('Fiche Creation Commande (P1)'!AB186=Q4,"OUI","NON") -> NON
D5: Type Cde | E5: =IF('Fiche Creation Commande (P1)'!AB161<>0,'Fiche Creation Commande (P1)'!AB161,"") -> INITIALE
D7: Nom CP | E7: =IF('Fiche Creation Commande (P1)'!B168<>0,'Fiche Creation Commande (P1)'!B168,"") -> B VELLERE | O7: Totaux et sous-totaux
N8: Page 1 | O8: ='Fiche Creation Commande (P1)'!$R$225 -> 30000
C9: Affaire | D9: 1 | E9: =IF('Fiche Creation Commande (P1)'!J165<>0,'Fiche Creation Commande (P1)'!J165,"") -> Projet de racco Gaudiere Amarenco | N9: Page 1+2 | O9: =$O$79 -> 0
D10: 2 | E10: =IF('Fiche Creation Commande (P1)'!J167<>0,'Fiche Creation Commande (P1)'!J167,"") -> MCPO2 Debenas | N10: Page 1+2+3 | O10: =$O$142 -> 0
D11: 3 | E11: =IF('Fiche Creation Commande (P1)'!J169<>0,'Fiche Creation Commande (P1)'!J169,"") | O11: sous-totaux
D12: 4 | E12: =IF('Fiche Creation Commande (P1)'!J172<>0,'Fiche Creation Commande (P1)'!J172,"") | N12: Montant Page 1 | O12: =O8 -> 30000
N13: Montant Page 2 | O13: =IF(O9<>0,O9-O8,"")
N14: Montant Page 3 | O14: =IF(O10<>0,O10-O9,"")
B16: Zone avec formule
B17: Zone d'impression
D18: CREATION COMMANDE : | J18: =IF(Q27<>0,IF(E4<>0,E4,""),"") | N18: =IF(Q27<>0,IF(E5<>0,E5,""),"") | P18: =IF(Q90<>0,"Page 02 / 03",IF(Q27<>0,"Page 02 / 02","Page ..…/.....")) -> Page ..…/..... | V18: =IF(Q27<>0,"Vous débutez la Page 2, une 3ème page est disponible plus bas.","Les rappels de la page précédente apparaîtront lorsque vous aurez saisie le poste 110 (Qté+Montant Unitaire HT") -> Les rappels de la page précédente apparaîtront lorsque vous aurez saisie le poste 110 (Qté+Montant Unitaire HT
B20: Demandeur | H20: Affaire | O20: =IF(Q27<>0,"Rappel Sous-Total Page 1","Total HT") -> Total HT
B21: Nom du Responsable Projet : | H21: =IF(Q27<>0,IF(E9<>0,CONCATENATE(E9," ",E10," ",E11," ",E12),""),"") | O21: =IF(Q27<>0,O8,"")
B22: =IF(Q27<>0,IF(E7<>0,E7,""),"")
O23: Total HT en euros
B24: 110 | M24: Date réception | O24: Qté | Q24: Montant Unitaire HT
B27: OTP | O27: Montant Total Ligne HT | Q27: =O25*Q25 -> 0
B29: 120 | M29: Date réception | O29: Qté | Q29: Montant Unitaire HT
B32: OTP | O32: Montant Total Ligne HT | Q32: =O30*Q30 -> 0
B34: 130 | M34: Date réception | O34: Qté | Q34: Montant Unitaire HT
B37: OTP | O37: Montant Total Ligne HT | Q37: =O35*Q35 -> 0
B39: 140 | M39: Date réception | O39: Qté | Q39: Montant Unitaire HT
B42: OTP | O42: Montant Total Ligne HT | Q42: =O40*Q40 -> 0
B44: 150 | M44: Date réception | O44: Qté | Q44: Montant Unitaire HT
B47: OTP | O47: Montant Total Ligne HT | Q47: =O45*Q45 -> 0
B49: 160 | M49: Date réception | O49: Qté | Q49: Montant Unitaire HT
B52: OTP | O52: Montant Total Ligne HT | Q52: =O50*Q50 -> 0
B54: 170 | M54: Date réception | O54: Qté | Q54: Montant Unitaire HT
B57: OTP | O57: Montant Total Ligne HT | Q57: =O55*Q55 -> 0
B59: 180 | M59: Date réception | O59: Qté | Q59: Montant Unitaire HT
B62: OTP | O62: Montant Total Ligne HT | Q62: =O60*Q60 -> 0
B64: 190 | M64: Date réception | O64: Qté | Q64: Montant Unitaire HT
B67: OTP | O67: Montant Total Ligne HT | Q67: =O65*Q65 -> 0
B69: 200 | M69: Date réception | O69: Qté | Q69: Montant Unitaire HT
B72: OTP | O72: Montant Total Ligne HT | Q72: =O70*Q70 -> 0
B74: 210 | M74: Date réception | O74: Qté | Q74: Montant Unitaire HT
...
